<?xml version="1.0"?>
<robot name="sperical_joint">
  <link name="base_link">
    <visual>
      <origin rpy="0 0 0" xyz="-0.254 0 0"/>
      <geometry>
        <mesh filename="package://spherical_joint/models/spherical_ball.stl" scale="0.001 0.001 0.001"/>
      </geometry>
    </visual>
  </link>

  <joint name="base_link_to_cup" type="floating">
    <parent link="base_link"/>
    <child link="cup"/>
    <origin xyz="0 0 0"/>
  </joint>

  <link name="cup">
    <visual>
      <origin rpy="-1.57 0 0" xyz="0 -0.284 0.142"/>
      <geometry>
        <mesh filename="package://spherical_joint/models/spherical_cup.stl" scale="0.001 0.001 0.001"/>
      </geometry>
    </visual>
  </link>
</robot>